Workbook

Sheet How to Use
B2: How to audit a client's freight quotation
B3: UAT version 1.0 (frozen 23 Oct 2026). One quotation per audit. Five steps. Everything in grey, the findings and the Summary sheet fill in automatically - no macros.
B5: 1 Collect documents | C5: The forwarder's quotation, the commercial invoice (CI), the packing list (PL) and any rate agreement or contract. Without an itemised quotation, CI or PL the status shows 'Insufficient Information'.
B6: 2 Enter shipment details | C6: Audit sheet, section 1: copy the cargo from the CI/PL (pieces, cartons and pallets separately, weight, volume, value) and answer 'PL volume covers all cargo?'. Record the Incoterm exactly as on the CI and the client's role (buyer or seller). In section 3, answer 'Requested by client?' for each service.
B7: 3 Enter the quotation charges | C7: Section 2: forwarder, date, freight validity and - only if stated - origin and destination charge validity (blank = Not Confirmed), currency, mode and containers, route, transit, free time; enter the cargo figures only if the quotation states them. Section 4: one row per quoted charge - Charge, Category, Basis, Rate, Status. Leave Currency blank for the quotation currency. Enter the forwarder's line total only if the quotation shows it (this is what makes a line 'Verified'). Enter Agreed rate only when a rate agreement was provided.
B8: 4 Review the automatic findings | C8: Section 5 shows the status, the firm charges, estimates, conditional and unpriced items, and the findings in priority order. Use the 'Reviewer flag' column to record your own judgement on a line (e.g. possible duplicate) - it becomes a finding with the line amount. Accept a weight or CBM difference only with a reason (Accept diff. = Yes).
B9: 5 Generate the audit summary | C9: Open the Summary sheet: it is already filled in. File > Print (or Download as PDF in Google Sheets). It is set to fit one page wide.
B11: Colour key
B12: Type here | C12: Input cell. Dropdowns appear where a fixed list applies.
B13: Calculated | C13: Formula - do not overwrite.
B15: Status (one per audit)
B16: Insufficient Information | C16: CI or PL missing, quotation not itemised, or no line can be calculated.
B17: Corrections Required | C17: At least one confirmed error: a line amount or stated total that does not reconcile, a rate above the agreed rate, or quoted pieces/packages that contradict the CI/PL.
B18: Needs Clarification | C18: No confirmed errors, but open questions or risks (e.g. unpriced or excluded requested services, at-cost items, expiring rates).
B19: Audit Complete — No Issues Identified | C19: Only when no error, question or risk is open. It cannot appear while requested services are unpriced, excluded or estimated.
B21: Finding types
B22: Error | C22: Confirmed and must be corrected by the forwarder.
B23: Question | C23: Must be clarified before the client proceeds. Amounts shown are 'under question', not confirmed savings.
B24: Risk | C24: Cost could change or is not covered by the quotation.
B26: Good to know
B27: • | C27: 'Verified' appears only when the forwarder's own line amount is entered and reconciles. Otherwise a line shows 'Calculated — Not Independently Verified'.
B28: • | C28: Quantities fill in from the basis: per container = containers quoted; per CBM = shipped CBM; per RT = greater of CBM and tonnes; per kg = chargeable kg (air uses the stated divisor, else the default in Lists). Use 'Qty / base override' for per-unit lines and for the base of % charges.
B29: • | C29: Statuses: Firm = in the firm figure · Estimate = shown separately · If required = conditional, only if the event occurs · At cost / TBC = no amount yet · Included / Excluded / Not applicable = no amount.
B30: • | C30: The tool never judges prices against 'the market' and holds no duty or VAT rates. Agreed rates are checked only when entered from a rate agreement.
B31: • | C31: Incoterm questions are raised only for services that Incoterms 2020 normally place on the other party (table in Lists). They are questions, not errors.
B32: • | C32: Up to 50 charge lines and 30 findings are shown. To start a new audit, use a fresh copy of the blank template.
B33: • | C33: A hidden sheet named 'Checks' runs the 20 checks with ordinary formulas. Do not edit or delete it. Settings (air divisor, validity warning, review threshold, rounding tolerance) are on the Lists sheet.

Sheet Audit
B1: MOVE · Freight Quotation Audit
B2: One quotation per audit. Yellow cells = type here · Grey cells = calculated · Dropdowns where shown. Checks run automatically.
B3: AUDIT STATUS | C3: =Checks!$AF$2 -> Not started | G3: =Checks!$AF$20 -> Known Firm Charges — Not All-In | J3: =Checks!$AF$10 -> 0 | L3: =Checks!$AF$3&" errors · "&Checks!$AF$4&" questions · "&Checks!$AF$5&" risks — see section 5" -> 0 errors · 0 questions · 0 risks — see section 5
B5: 1 SHIPMENT INFORMATION From the commercial invoice, packing list and the client's request
B6: Audit reference | G6: Audit date
B7: Client | G7: Client role in the sale
B8: Commercial Incoterm | G8: Named place
B9: Port / airport of loading | G9: Port / airport of discharge
B10: Pickup address | G10: Delivery address
B11: Cargo ready date | G11: Commodity
B12: HS code | G12: Goods value (from CI)
B13: Goods value currency | G13: Pieces
B14: Cartons (count) | G14: Pallets (count; 0 if none)
B15: Gross weight (kg) | G15: Volume as shipped (CBM)
B16: Package / pallet dimensions | G16: Stackable
B17: Wood packaging | G17: Special cargo (DG, oversize, overweight)
... B21: Prepared by | G21: PL volume covers all cargo?
B22: 2 QUOTATION INFORMATION The quotation being audited
B23: Forwarder | G23: Quotation reference
B24: Quotation source and date | G24: Freight valid until
B25: Quotation currency | G25: Mode
B26: Containers (quantity) | G26: Container type
B27: Quoted term as written | G27: Routing (direct / via)
B28: Transit time | G28: Free time at destination (days)
B29: Load plan confirmed by forwarder | G29: Quoted route matches the request
B30: Air divisor stated (cm3/kg) | G30: Forwarder's stated total
B31: Other currency 1 (code) | G31: Rate: 1 unit = ? quote currency
B32: Other currency 2 (code) | G32: Rate: 1 unit = ? quote currency
B33: Origin charges valid until (blank = Not Confirmed) | G33: Destination charges valid until (blank = Not Confirmed)
B34: Cargo basis (blank Quoted = not stated) | C34: CI/PL (auto) | D34: Quoted | E34: Difference | F34: Diff % | G34: Accept diff.? | H34: Check (auto)
B35: Pieces | C35: =IF(Audit!$J$13="","",Audit!$J$13) | E35: =IF(OR(C35="",D35=""),"",D35-C35) | F35: =IF(OR(C35="",D35="",C35=0),"",(D35-C35)/C35) | G35: Must match | H35: =IF(D35="","Not stated in quotation",IF(C35="","CI/PL value missing",IF(D35=C35,"Matches","ERROR - does not match the CI/PL"))) -> Not stated in quotation
B36: Packages (cartons or pallets) | C36: =IF(Audit!$C$14="","",Audit!$C$14&" ctns / "&IF(Audit!$J$14="","0",Audit!$J$14)&" plts") | G36: Must match | H36: =IF(D36="","Not stated in quotation",IF(AND(Audit!$C$14="",Audit!$J$14=""),"CI/PL value missing",IF(D36=Audit!$C$14,"Matches cartons",IF(AND(ISNUMBER(Audit!$J$14),D36=Audit!$J$14),"Matches pallets","ERROR - matches neither cartons nor pallets")))) -> Not stated in quotation
B37: Gross weight (kg) | C37: =IF(Audit!$C$15="","",Audit!$C$15) | E37: =IF(OR(C37="",D37=""),"",D37-C37) | F37: =IF(OR(C37="",D37="",C37=0),"",(D37-C37)/C37) | H37: =IF(D37="","Not stated in quotation",IF(C37="","CI/PL value missing",IF(D37=C37,"Matches",IF(G37="Yes","Difference accepted by auditor","Review - differs by "&TEXT(E37,"#,##0.###")&" ("&TEXT(F37,"0.0%")&")")))) -> Not stated in quotation
B38: Volume (CBM) | C38: =IF(Audit!$J$15="","",Audit!$J$15) | E38: =IF(OR(C38="",D38=""),"",D38-C38) | F38: =IF(OR(C38="",D38="",C38=0),"",(D38-C38)/C38) | H38: =IF(D38="","Not stated in quotation",IF(C38="","CI/PL value missing",IF(D38=C38,"Matches",IF(G38="Yes","Difference accepted by auditor","Review - differs by "&TEXT(E38,"#,##0.###")&" ("&TEXT(F38,"0.0%")&")")))) -> Not stated in quotation
B39: Revenue tonnes (auto, LCL) | C39: =Checks!$AF$30 | G39: Chargeable weight kg (auto) | J39: =Checks!$AF$31 | L39: =IF(Audit!$J$25="Air","Divisor used: "&Checks!$AF$32,"")
B41: 3 REQUESTED SERVICES & COVERAGE Coverage fills in from the charge lines; only mark a service that has no lines
B42: Service | C42: Requested by client? | D42: Found in quotation (auto) | G42: Mark if no lines | H42: Coverage (auto) | J42: Firm amount (auto) | M42: Normally paid by (auto)
B43: Pickup | D43: =Checks!$H$55 -> No lines | H43: =Checks!$J$55 -> - | J43: =Checks!$K$55 -> 0 | M43: =Checks!$L$55
B44: Export & origin | D44: =Checks!$H$56 -> No lines | H44: =Checks!$J$56 -> - | J44: =Checks!$K$56 -> 0 | M44: =Checks!$L$56
B45: Main freight | D45: =Checks!$H$57 -> No lines | H45: =Checks!$J$57 -> - | J45: =Checks!$K$57 -> 0 | M45: =Checks!$L$57
...

Sheet Summary
A1: MOVE SUPPLY CHAIN | E1: ="Prepared for: "&Audit!$C$7 -> Prepared for:
A2: Freight Quotation Audit - Summary | E2: ="By: "&Audit!$C$21&" · Audit date: "&IF(ISNUMBER(Audit!$J$6),TEXT(Audit!$J$6,"d mmm yyyy"),"") -> By: · Audit date:
E3: ="Reference: "&Audit!$C$6 -> Reference:
A5: Status | C5: =Checks!$AF$2 -> Not started | E5: =Checks!$AF$21 -> Enter shipment, quotation and charge details to start the audit.
A7: Quotation audited
A8: Forwarder | C8: =Audit!$C$23 -> 0 | D8: Validity | E8: ="Freight: "&IF(ISNUMBER(Audit!$J$24),TEXT(Audit!$J$24,"d mmm yyyy"),"not stated")&" · origin charges: "&IF(ISNUMBER(Audit!$C$33),TEXT(Audit!$C$33,"d mmm yyyy"),"Not Confirmed")&" · destination charges: "&IF(ISNUMBER(Audit!$J$33),TEXT(Audit!$J$33,"d mmm yyyy"),"Not Confirmed") -> Freight: not stated · origin charges: Not Confirmed · destination charges: Not Confirmed
A9: Service | C9: =Audit!$J$25&IF(Audit!$J$25="Sea FCL"," · "&Audit!$C$26&" x "&Audit!$J$26,"") | D9: Route | E9: =Audit!$C$9&" to "&Audit!$J$9&IF(Audit!$J$27<>""," ("&Audit!$J$27&")","") -> to
A10: Shipment | C10: =Audit!$J$13&" pcs · "&Audit!$C$14&" cartons · "&Audit!$J$14&" pallets" -> pcs · cartons · pallets | D10: Cargo | E10: =TEXT(Audit!$C$15,"#,##0.##")&" kg · "&TEXT(Audit!$J$15,"#,##0.###")&" CBM · "&Audit!$C$8&" "&Audit!$J$8 -> 0 kg · 0 CBM ·
A12: Cost picture
A13: =Checks!$AF$20 -> Known Firm Charges — Not All-In | D13: =Checks!$AF$10 -> 0 | E13: =Checks!$AF$22 -> Not all-in:
A14: Estimates (not in firm figure) | D14: =Checks!$AF$11 -> 0
A15: Conditional charges - only if they occur | D15: =Checks!$AF$13 -> 0 | E15: ="Plus "&Checks!$AF$14&" if-required item(s) with no amount" -> Plus 0 if-required item(s) with no amount
A16: Unpriced items (at cost / TBC) | D16: =Checks!$AF$15 -> 0
A17: Confirmed discrepancies (Errors, net) | D17: =Checks!$AF$16 -> 0
A18: Amount under question - NOT a confirmed saving | D18: =Checks!$AF$17 -> 0
A20: Requested services
A21: Service | C21: Requested | D21: Coverage | E21: Normally paid by (Incoterm) | F21: Firm amount
A22: =Audit!$B$43 -> Pickup | C22: =IF(Audit!$C$43="","-",Audit!$C$43) -> - | D22: =Audit!$H$43 -> - | E22: =IF(Audit!$M$43="","-",Audit!$M$43) -> - | F22: =Audit!$J$43 -> 0
A23: =Audit!$B$44 -> Export & origin | C23: =IF(Audit!$C$44="","-",Audit!$C$44) -> - | D23: =Audit!$H$44 -> - | E23: =IF(Audit!$M$44="","-",Audit!$M$44) -> - | F23: =Audit!$J$44 -> 0
A24: =Audit!$B$45 -> Main freight | C24: =IF(Audit!$C$45="","-",Audit!$C$45) -> - | D24: =Audit!$H$45 -> - | E24: =IF(Audit!$M$45="","-",Audit!$M$45) -> - | F24: =Audit!$J$45 -> 0
A25: =Audit!$B$46 -> Destination port & handling | C25: =IF(Audit!$C$46="","-",Audit!$C$46) -> - | D25: =Audit!$H$46 -> - | E25: =IF(Audit!$M$46="","-",Audit!$M$46) -> - | F25: =Audit!$J$46 -> 0
A26: =Audit!$B$47 -> Import clearance | C26: =IF(Audit!$C$47="","-",Audit!$C$47) -> - | D26: =Audit!$H$47 -> - | E26: =IF(Audit!$M$47="","-",Audit!$M$47) -> - | F26: =Audit!$J$47 -> 0
A27: =Audit!$B$48 -> Delivery | C27: =IF(Audit!$C$48="","-",Audit!$C$48) -> - | D27: =Audit!$H$48 -> - | E27: =IF(Audit!$M$48="","-",Audit!$M$48) -> - | F27: =Audit!$J$48 -> 0
A28: =Audit!$B$49 -> Duties & taxes | C28: =IF(Audit!$C$49="","-",Audit!$C$49) -> - | D28: =Audit!$H$49 -> - | E28: =IF(Audit!$M$49="","-",Audit!$M$49) -> - | F28: =Audit!$J$49 -> 0
A30: Findings and recommended actions
A31: # | B31: Type | C31: Charge | D31: Issue | E31: Recommended correction or question | F31: Amount at stake
A32: =Audit!$A$119 | B32: =Audit!$B$119 | C32: =Audit!$C$119 | D32: =Audit!$E$119 | E32: =Audit!$N$119 | F32: =Audit!$Q$119
A33: =Audit!$A$120 | B33: =Audit!$B$120 | C33: =Audit!$C$120 | D33: =Audit!$E$120 | E33: =Audit!$N$120 | F33: =Audit!$Q$120
A34: =Audit!$A$121 | B34: =Audit!$B$121 | C34: =Audit!$C$121 | D34: =Audit!$E$121 | E34: =Audit!$N$121 | F34: =Audit!$Q$121
A35: =Audit!$A$122 | B35: =Audit!$B$122 | C35: =Audit!$C$122 | D35: =Audit!$E$122 | E35: =Audit!$N$122 | F35: =Audit!$Q$122
A36: =Audit!$A$123 | B36: =Audit!$B$123 | C36: =Audit!$C$123 | D36: =Audit!$E$123 | E36: =Audit!$N$123 | F36: =Audit!$Q$123
A37: =Audit!$A$124 | B37: =Audit!$B$124 | C37: =Audit!$C$124 | D37: =Audit!$E$124 | E37: =Audit!$N$124 | F37: =Audit!$Q$124
A38: =Audit!$A$125 | B38: =Audit!$B$125 | C38: =Audit!$C$125 | D38: =Audit!$E$125 | E38: =Audit!$N$125 | F38: =Audit!$Q$125
A39: =Audit!$A$126 | B39: =Audit!$B$126 | C39: =Audit!$C$126 | D39: =Audit!$E$126 | E39: =Audit!$N$126 | F39: =Audit!$Q$126
A40: =Audit!$A$127 | B40: =Audit!$B$127 | C40: =Audit!$C$127 | D40: =Audit!$E$127 | E40: =Audit!$N$127 | F40: =Audit!$Q$127
A41: =Audit!$A$128 | B41: =Audit!$B$128 | C41: =Audit!$C$128 | D41: =Audit!$E$128 | E41: =Audit!$N$128 | F41: =Audit!$Q$128
A42: =Audit!$A$129 | B42: =Audit!$B$129 | C42: =Audit!$C$129 | D42: =Audit!$E$129 | E42: =Audit!$N$129 | F42: =Audit!$Q$129
A43: =Audit!$A$130 | B43: =Audit!$B$130 | C43: =Audit!$C$130 | D43: =Audit!$E$130 | E43: =Audit!$N$130 | F43: =Audit!$Q$130
A44: =Audit!$A$131 | B44: =Audit!$B$131 | C44: =Audit!$C$131 | D44: =Audit!$E$131 | E44: =Audit!$N$131 | F44: =Audit!$Q$131
A45: =Audit!$A$132 | B45: =Audit!$B$132 | C45: =Audit!$C$132 | D45: =Audit!$E$132 | E45: =Audit!$N$132 | F45: =Audit!$Q$132
...

Sheet Lists
A1: Lists & settings (used by the dropdowns and checks; edit settings in column B rows 41-44 only)
A3: Category | B3: Group | C3: Service | E3: Basis | G3: Status | I3: Incoterm | J3: Pickup | K3: Export & origin | L3: Main freight | M3: Destination port & handling | N3: Import clearance | O3: Delivery | P3: Duties & taxes
A4: O1 Pickup | B4: Origin | C4: Pickup | E4: per container | G4: Firm | I4: EXW | J4: Buyer | K4: Buyer | L4: Buyer | M4: Buyer | N4: Buyer | O4: Buyer | P4: Buyer
A5: O2 Origin terminal & handling | B5: Origin | C5: Export & origin | E5: per B/L | G5: Estimate | I5: FCA | J5: Buyer | K5: Shared | L5: Buyer | M5: Buyer | N5: Buyer | O5: Buyer | P5: Buyer
A6: O3 Export docs, filing & clearance | B6: Origin | C6: Export & origin | E6: per shipment | G6: If required | I6: FAS | J6: Seller | K6: Shared | L6: Buyer | M6: Buyer | N6: Buyer | O6: Buyer | P6: Buyer
A7: F1 Base freight | B7: Main Freight | C7: Main freight | E7: per declaration / set | G7: At cost | I7: FOB | J7: Seller | K7: Seller | L7: Buyer | M7: Buyer | N7: Buyer | O7: Buyer | P7: Buyer
A8: F2 Freight surcharges | B8: Main Freight | C8: Main freight | E8: per CBM | G8: TBC | I8: CFR | J8: Seller | K8: Seller | L8: Seller | M8: Shared | N8: Buyer | O8: Buyer | P8: Buyer
A9: D1 Destination terminal & port | B9: Destination | C9: Destination port & handling | E9: per RT (CBM or tonne) | G9: Included | I9: CIF | J9: Seller | K9: Seller | L9: Seller | M9: Shared | N9: Buyer | O9: Buyer | P9: Buyer
A10: D2 Destination docs & handling | B10: Destination | C10: Destination port & handling | E10: per kg | G10: Excluded | I10: CPT | J10: Seller | K10: Seller | L10: Seller | M10: Shared | N10: Buyer | O10: Shared | P10: Buyer
A11: D3 Import customs clearance | B11: Destination | C11: Import clearance | E11: per unit (enter qty) | G11: Not applicable | I11: CIP | J11: Seller | K11: Seller | L11: Seller | M11: Shared | N11: Buyer | O11: Shared | P11: Buyer
A12: D4 Delivery | B12: Destination | C12: Delivery | E12: % of base (enter base) | I12: DAP | J12: Seller | K12: Seller | L12: Seller | M12: Seller | N12: Buyer | O12: Seller | P12: Buyer
A13: T1 Import duty | B13: Duties/Taxes | C13: Duties & taxes | E13: lump sum | I13: DPU | J13: Seller | K13: Seller | L13: Seller | M13: Seller | N13: Buyer | O13: Seller | P13: Buyer
A14: T2 Import VAT / GST | B14: Duties/Taxes | C14: Duties & taxes | E14: at cost | I14: DDP | J14: Seller | K14: Seller | L14: Seller | M14: Seller | N14: Seller | O14: Seller | P14: Seller
A15: T3 Tax-related fees | B15: Duties/Taxes | C15: Duties & taxes
A16: Unclassified | B16: Other | C16: Other | I16: Who normally pays each service under Incoterms 2020 (general practice; 'Shared' = depends on named place or terminal practice, so no question is raised).
A20: Reviewer flag | B20: Issue | C20: Default explanation | E20: Recommended action | G20: Use line amount
A21: Possible duplicate | B21: Possible duplicate charge | C21: The same service may already be charged in another line. | E21: Ask whether this service is already included elsewhere; remove it if duplicated. | G21: 1
A22: Unclear / unexplained | B22: Charge not explained | C22: The charge name or purpose is not clear from the quotation. | E22: Ask the forwarder what this charge covers and why it applies. | G22: 1
A23: Not applicable to this cargo | B23: May not apply to this shipment | C23: The charge does not appear to apply to this cargo or route. | E23: Ask the forwarder to remove it or explain why it applies. | G23: 1
A24: Questionable basis or unit | B24: Charging basis looks wrong | C24: The unit or quantity used does not suit this charge. | E24: Ask the forwarder to confirm the unit and quantity used. | G24: 0
A25: Other - see note | B25: Reviewer query | C25: See the note on this line. | E25: Raise the note with the forwarder. | G25: 0
A29: Services (order fixed)
A30: Pickup
A31: Export & origin
A32: Main freight
A33: Destination port & handling
A34: Import clearance
A35: Delivery
A36: Duties & taxes
A40: Setting | B40: Value | C40: Meaning
A41: Default air volume divisor (cm3 per kg) | B41: 6000 | C41: Used only when the quotation or carrier tariff states no divisor.
A42: Validity warning (days) | B42: 7 | C42: A Risk is raised when rates expire within this many days of the audit date.
A43: Weight / CBM review threshold (%) | B43: 0 | C43: 0 = every difference is raised for review. Differences are never accepted automatically.
A44: Rounding tolerance (amount) | B44: 0.01 | C44: Differences up to this amount are treated as rounding when reconciling line totals.

Sheet Checks
A1: Line | B1: Name | C1: Category | D1: Service | E1: Group | F1: Status | G1: Basis code | H1: Rate | I1: Currency | J1: FX | K1: Qty used | L1: Pre-tax (line cur) | M1: Incl. tax (line cur) | N1: Total (quote cur) | O1: Priced | P1: Fwd total | Q1: Verification | R1: Diff (quote cur) | S1: Agreed excess | T1: Flag | U1: Dup | V1: In scope | W1: Unpriced | X1: Q kind | Y1: Tax
A2: 1 | B2: =TRIM(Audit!$B$54) | C2: =Audit!$C$54&"" | D2: =IF(B2="","",IF(C2="","Other",IFERROR(INDEX(Lists!$C$4:$C$16,MATCH(C2,Lists!$A$4:$A$16,0)),"Other"))) | E2: =IF(B2="","",IF(C2="","Other",IFERROR(INDEX(Lists!$B$4:$B$16,MATCH(C2,Lists!$A$4:$A$16,0)),"Other"))) | F2: =Audit!$G$54&"" | G2: =IFERROR(MATCH(Audit!$D$54,Lists!$E$4:$E$14,0),0) -> 0 | H2: =IF(ISNUMBER(Audit!$E$54),Audit!$E$54,"") | I2: =IF(TRIM(Audit!$F$54)="",Audit!$C$25,TRIM(Audit!$F$54)) -> 0 | J2: =IF(OR(I2=Audit!$C$25,I2=""),1,IF(AND(I2=Audit!$C$31,ISNUMBER(Audit!$J$31)),Audit!$J$31,IF(AND(I2=Audit!$C$32,ISNUMBER(Audit!$J$32)),Audit!$J$32,""))) -> 1 | K2: =IF(B2="","",IF(ISNUMBER(Audit!$I$54),Audit!$I$54,IF(G2=0,"",CHOOSE(G2,IF(ISNUMBER(Audit!$C$26),Audit!$C$26,1),1,1,1,$AF$33,$AF$30,$AF$31,1,"",1,0)))) | L2: =IF(O2=1,ROUND(MAX(H2*K2,IF(ISNUMBER(Audit!$J$54),Audit!$J$54,0)),2),"") | M2: =IF(O2=1,ROUND(L2*(1+Y2),2),"") | N2: =IF(O2=1,IF(ISNUMBER(J2),ROUND(M2*J2,2),""),"") | O2: =IF(AND(B2<>"",OR(F2="Firm",F2="Estimate",F2="If required"),ISNUMBER(H2),G2>0,G2<>11,ISNUMBER(K2)),1,0) -> 0 | P2: =IF(ISNUMBER(Audit!$L$54),Audit!$L$54,"") | Q2: =IF(B2="","",IF(OR(F2="At cost",F2="TBC"),"Not priced ("&F2&")",IF(OR(F2="Included",F2="Excluded",F2="Not applicable"),F2,IF(F2="","Status missing",IF(AND(F2="If required",NOT(ISNUMBER(H2))),"Not priced (if required)",IF(G2=0,"Basis missing",IF(G2=11,"Not priced (at cost)",IF(NOT(ISNUMBER(H2)),"Rate missing",IF(AND(G2=9,NOT(ISNUMBER(Audit!$I$54))),"Base amount missing",IF(NOT(ISNUMBER(J2)),"Exchange rate missing",IF(NOT(ISNUMBER(P2)),"Calculated — Not Independently Verified",IF(ABS(R2)<=Lists!$B$44,"Verified","Error - differs by "&TEXT(R2,"#,##0.00")&" "&I2)))))))))))) | R2: =IF(AND(O2=1,ISNUMBER(P2)),IF(ABS(P2-L2)<=ABS(P2-M2),P2-L2,P2-M2),"") | S2: =IF(AND(O2=1,ISNUMBER(Audit!$M$54),ISNUMBER(J2)),IF(H2-Audit!$M$54>0.005,ROUND((H2-Audit!$M$54)*K2*(1+Y2)*J2,2),0),0) -> 0 | T2: =Audit!$N$54&"" | U2: =IF(B2="",0,IF(COUNTIFS($B$2:$B$51,B2,$D$2:$D$51,D2)>1,1,0)) -> 0 | V2: =IF(D2="","",IFERROR(INDEX(Audit!$C$43:$C$49,MATCH(D2,Lists!$A$30:$A$36,0)),"")) | W2: =IF(AND(B2<>"",OR(F2="At cost",F2="TBC",AND(F2<>"If required",G2=11))),1,0) -> 0 | X2: =IF(B2="","",IF(T2<>"","flag",IF(F2="","status",IF(AND(G2=0,OR(F2="Firm",F2="Estimate",AND(F2="If required",ISNUMBER(H2)))),"basis",IF(AND(OR(F2="Firm",F2="Estimate"),G2<>11,NOT(ISNUMBER(H2))),"rate",IF(AND(O2=0,G2=9,OR(F2="Firm",F2="Estimate"),ISNUMBER(H2)),"base",IF(OR(C2="",C2="Unclassified"),"unclass",IF(U2=1,"dup",IF(AND(Audit!$C$19="Yes",O2=1,NOT(ISNUMBER(Audit!$M$54))),"noagree",""))))))))) | Y2: =IF(ISNUMBER(Audit!$K$54),Audit!$K$54,0) -> 0 | Z2: =IF(AND(F2="Firm",O2=1,ISNUMBER(J2)),L2*J2,0) -> 0 | AE2: Status | AF2: =IF(AF34=1,"Not started",IF(AF6=1,"Insufficient Information",IF(AF3>0,"Corrections Required",IF(AF4+AF5>0,"Needs Clarification","Audit Complete — No Issues Identified")))) -> Not started | AH2: 1 | AI2: =IFERROR(SMALL($J$70:$J$470,AH2),"") | AJ2: =IF(AI2="","",MATCH(AI2,$J$70:$J$470,0)) | AL2: 1 | AM2: =IFERROR(SMALL($K$70:$K$470,AL2),"") | AN2: =IF(AM2="","",MATCH(AM2,$K$70:$K$470,0))
A3: 2 | B3: =TRIM(Audit!$B$55) | C3: =Audit!$C$55&"" | D3: =IF(B3="","",IF(C3="","Other",IFERROR(INDEX(Lists!$C$4:$C$16,MATCH(C3,Lists!$A$4:$A$16,0)),"Other"))) | E3: =IF(B3="","",IF(C3="","Other",IFERROR(INDEX(Lists!$B$4:$B$16,MATCH(C3,Lists!$A$4:$A$16,0)),"Other"))) | F3: =Audit!$G$55&"" | G3: =IFERROR(MATCH(Audit!$D$55,Lists!$E$4:$E$14,0),0) -> 0 | H3: =IF(ISNUMBER(Audit!$E$55),Audit!$E$55,"") | I3: =IF(TRIM(Audit!$F$55)="",Audit!$C$25,TRIM(Audit!$F$55)) -> 0 | J3: =IF(OR(I3=Audit!$C$25,I3=""),1,IF(AND(I3=Audit!$C$31,ISNUMBER(Audit!$J$31)),Audit!$J$31,IF(AND(I3=Audit!$C$32,ISNUMBER(Audit!$J$32)),Audit!$J$32,""))) -> 1 | K3: =IF(B3="","",IF(ISNUMBER(Audit!$I$55),Audit!$I$55,IF(G3=0,"",CHOOSE(G3,IF(ISNUMBER(Audit!$C$26),Audit!$C$26,1),1,1,1,$AF$33,$AF$30,$AF$31,1,"",1,0)))) | L3: =IF(O3=1,ROUND(MAX(H3*K3,IF(ISNUMBER(Audit!$J$55),Audit!$J$55,0)),2),"") | M3: =IF(O3=1,ROUND(L3*(1+Y3),2),"") | N3: =IF(O3=1,IF(ISNUMBER(J3),ROUND(M3*J3,2),""),"") | O3: =IF(AND(B3<>"",OR(F3="Firm",F3="Estimate",F3="If required"),ISNUMBER(H3),G3>0,G3<>11,ISNUMBER(K3)),1,0) -> 0 | P3: =IF(ISNUMBER(Audit!$L$55),Audit!$L$55,"") | Q3: =IF(B3="","",IF(OR(F3="At cost",F3="TBC"),"Not priced ("&F3&")",IF(OR(F3="Included",F3="Excluded",F3="Not applicable"),F3,IF(F3="","Status missing",IF(AND(F3="If required",NOT(ISNUMBER(H3))),"Not priced (if required)",IF(G3=0,"Basis missing",IF(G3=11,"Not priced (at cost)",IF(NOT(ISNUMBER(H3)),"Rate missing",IF(AND(G3=9,NOT(ISNUMBER(Audit!$I$55))),"Base amount missing",IF(NOT(ISNUMBER(J3)),"Exchange rate missing",IF(NOT(ISNUMBER(P3)),"Calculated — Not Independently Verified",IF(ABS(R3)<=Lists!$B$44,"Verified","Error - differs by "&TEXT(R3,"#,##0.00")&" "&I3)))))))))))) | R3: =IF(AND(O3=1,ISNUMBER(P3)),IF(ABS(P3-L3)<=ABS(P3-M3),P3-L3,P3-M3),"") | S3: =IF(AND(O3=1,ISNUMBER(Audit!$M$55),ISNUMBER(J3)),IF(H3-Audit!$M$55>0.005,ROUND((H3-Audit!$M$55)*K3*(1+Y3)*J3,2),0),0) -> 0 | T3: =Audit!$N$55&"" | U3: =IF(B3="",0,IF(COUNTIFS($B$2:$B$51,B3,$D$2:$D$51,D3)>1,1,0)) -> 0 | V3: =IF(D3="","",IFERROR(INDEX(Audit!$C$43:$C$49,MATCH(D3,Lists!$A$30:$A$36,0)),"")) | W3: =IF(AND(B3<>"",OR(F3="At cost",F3="TBC",AND(F3<>"If required",G3=11))),1,0) -> 0 | X3: =IF(B3="","",IF(T3<>"","flag",IF(F3="","status",IF(AND(G3=0,OR(F3="Firm",F3="Estimate",AND(F3="If required",ISNUMBER(H3)))),"basis",IF(AND(OR(F3="Firm",F3="Estimate"),G3<>11,NOT(ISNUMBER(H3))),"rate",IF(AND(O3=0,G3=9,OR(F3="Firm",F3="Estimate"),ISNUMBER(H3)),"base",IF(OR(C3="",C3="Unclassified"),"unclass",IF(U3=1,"dup",IF(AND(Audit!$C$19="Yes",O3=1,NOT(ISNUMBER(Audit!$M$55))),"noagree",""))))))))) | Y3: =IF(ISNUMBER(Audit!$K$55),Audit!$K$55,0) -> 0 | Z3: =IF(AND(F3="Firm",O3=1,ISNUMBER(J3)),L3*J3,0) -> 0 | AE3: Errors | AF3: =SUMIFS($B$70:$B$470,$C$70:$C$470,"Error") -> 0 | AH3: 2 | AI3: =IFERROR(SMALL($J$70:$J$470,AH3),"") | AJ3: =IF(AI3="","",MATCH(AI3,$J$70:$J$470,0)) | AL3: 2 | AM3: =IFERROR(SMALL($K$70:$K$470,AL3),"") | AN3: =IF(AM3="","",MATCH(AM3,$K$70:$K$470,0))
A4: 3 | B4: =TRIM(Audit!$B$56) | C4: =Audit!$C$56&"" | D4: =IF(B4="","",IF(C4="","Other",IFERROR(INDEX(Lists!$C$4:$C$16,MATCH(C4,Lists!$A$4:$A$16,0)),"Other"))) | E4: =IF(B4="","",IF(C4="","Other",IFERROR(INDEX(Lists!$B$4:$B$16,MATCH(C4,Lists!$A$4:$A$16,0)),"Other"))) | F4: =Audit!$G$56&"" | G4: =IFERROR(MATCH(Audit!$D$56,Lists!$E$4:$E$14,0),0) -> 0 | H4: =IF(ISNUMBER(Audit!$E$56),Audit!$E$56,"") | I4: =IF(TRIM(Audit!$F$56)="",Audit!$C$25,TRIM(Audit!$F$56)) -> 0 | J4: =IF(OR(I4=Audit!$C$25,I4=""),1,IF(AND(I4=Audit!$C$31,ISNUMBER(Audit!$J$31)),Audit!$J$31,IF(AND(I4=Audit!$C$32,ISNUMBER(Audit!$J$32)),Audit!$J$32,""))) -> 1 | K4: =IF(B4="","",IF(ISNUMBER(Audit!$I$56),Audit!$I$56,IF(G4=0,"",CHOOSE(G4,IF(ISNUMBER(Audit!$C$26),Audit!$C$26,1),1,1,1,$AF$33,$AF$30,$AF$31,1,"",1,0)))) | L4: =IF(O4=1,ROUND(MAX(H4*K4,IF(ISNUMBER(Audit!$J$56),Audit!$J$56,0)),2),"") | M4: =IF(O4=1,ROUND(L4*(1+Y4),2),"") | N4: =IF(O4=1,IF(ISNUMBER(J4),ROUND(M4*J4,2),""),"") | O4: =IF(AND(B4<>"",OR(F4="Firm",F4="Estimate",F4="If required"),ISNUMBER(H4),G4>0,G4<>11,ISNUMBER(K4)),1,0) -> 0 | P4: =IF(ISNUMBER(Audit!$L$56),Audit!$L$56,"") | Q4: =IF(B4="","",IF(OR(F4="At cost",F4="TBC"),"Not priced ("&F4&")",IF(OR(F4="Included",F4="Excluded",F4="Not applicable"),F4,IF(F4="","Status missing",IF(AND(F4="If required",NOT(ISNUMBER(H4))),"Not priced (if required)",IF(G4=0,"Basis missing",IF(G4=11,"Not priced (at cost)",IF(NOT(ISNUMBER(H4)),"Rate missing",IF(AND(G4=9,NOT(ISNUMBER(Audit!$I$56))),"Base amount missing",IF(NOT(ISNUMBER(J4)),"Exchange rate missing",IF(NOT(ISNUMBER(P4)),"Calculated — Not Independently Verified",IF(ABS(R4)<=Lists!$B$44,"Verified","Error - differs by "&TEXT(R4,"#,##0.00")&" "&I4)))))))))))) | R4: =IF(AND(O4=1,ISNUMBER(P4)),IF(ABS(P4-L4)<=ABS(P4-M4),P4-L4,P4-M4),"") | S4: =IF(AND(O4=1,ISNUMBER(Audit!$M$56),ISNUMBER(J4)),IF(H4-Audit!$M$56>0.005,ROUND((H4-Audit!$M$56)*K4*(1+Y4)*J4,2),0),0) -> 0 | T4: =Audit!$N$56&"" | U4: =IF(B4="",0,IF(COUNTIFS($B$2:$B$51,B4,$D$2:$D$51,D4)>1,1,0)) -> 0 | V4: =IF(D4="","",IFERROR(INDEX(Audit!$C$43:$C$49,MATCH(D4,Lists!$A$30:$A$36,0)),"")) | W4: =IF(AND(B4<>"",OR(F4="At cost",F4="TBC",AND(F4<>"If required",G4=11))),1,0) -> 0 | X4: =IF(B4="","",IF(T4<>"","flag",IF(F4="","status",IF(AND(G4=0,OR(F4="Firm",F4="Estimate",AND(F4="If required",ISNUMBER(H4)))),"basis",IF(AND(OR(F4="Firm",F4="Estimate"),G4<>11,NOT(ISNUMBER(H4))),"rate",IF(AND(O4=0,G4=9,OR(F4="Firm",F4="Estimate"),ISNUMBER(H4)),"base",IF(OR(C4="",C4="Unclassified"),"unclass",IF(U4=1,"dup",IF(AND(Audit!$C$19="Yes",O4=1,NOT(ISNUMBER(Audit!$M$56))),"noagree",""))))))))) | Y4: =IF(ISNUMBER(Audit!$K$56),Audit!$K$56,0) -> 0 | Z4: =IF(AND(F4="Firm",O4=1,ISNUMBER(J4)),L4*J4,0) -> 0 | AE4: Questions | AF4: =SUMIFS($B$70:$B$470,$C$70:$C$470,"Question") -> 0 | AH4: 3 | AI4: =IFERROR(SMALL($J$70:$J$470,AH4),"") | AJ4: =IF(AI4="","",MATCH(AI4,$J$70:$J$470,0)) | AL4: 3 | AM4: =IFERROR(SMALL($K$70:$K$470,AL4),"") | AN4: =IF(AM4="","",MATCH(AM4,$K$70:$K$470,0))
A5: 4 | B5: =TRIM(Audit!$B$57) | C5: =Audit!$C$57&"" | D5: =IF(B5="","",IF(C5="","Other",IFERROR(INDEX(Lists!$C$4:$C$16,MATCH(C5,Lists!$A$4:$A$16,0)),"Other"))) | E5: =IF(B5="","",IF(C5="","Other",IFERROR(INDEX(Lists!$B$4:$B$16,MATCH(C5,Lists!$A$4:$A$16,0)),"Other"))) | F5: =Audit!$G$57&"" | G5: =IFERROR(MATCH(Audit!$D$57,Lists!$E$4:$E$14,0),0) -> 0 | H5: =IF(ISNUMBER(Audit!$E$57),Audit!$E$57,"") | I5: =IF(TRIM(Audit!$F$57)="",Audit!$C$25,TRIM(Audit!$F$57)) -> 0 | J5: =IF(OR(I5=Audit!$C$25,I5=""),1,IF(AND(I5=Audit!$C$31,ISNUMBER(Audit!$J$31)),Audit!$J$31,IF(AND(I5=Audit!$C$32,ISNUMBER(Audit!$J$32)),Audit!$J$32,""))) -> 1 | K5: =IF(B5="","",IF(ISNUMBER(Audit!$I$57),Audit!$I$57,IF(G5=0,"",CHOOSE(G5,IF(ISNUMBER(Audit!$C$26),Audit!$C$26,1),1,1,1,$AF$33,$AF$30,$AF$31,1,"",1,0)))) | L5: =IF(O5=1,ROUND(MAX(H5*K5,IF(ISNUMBER(Audit!$J$57),Audit!$J$57,0)),2),"") | M5: =IF(O5=1,ROUND(L5*(1+Y5),2),"") | N5: =IF(O5=1,IF(ISNUMBER(J5),ROUND(M5*J5,2),""),"") | O5: =IF(AND(B5<>"",OR(F5="Firm",F5="Estimate",F5="If required"),ISNUMBER(H5),G5>0,G5<>11,ISNUMBER(K5)),1,0) -> 0 | P5: =IF(ISNUMBER(Audit!$L$57),Audit!$L$57,"") | Q5: =IF(B5="","",IF(OR(F5="At cost",F5="TBC"),"Not priced ("&F5&")",IF(OR(F5="Included",F5="Excluded",F5="Not applicable"),F5,IF(F5="","Status missing",IF(AND(F5="If required",NOT(ISNUMBER(H5))),"Not priced (if required)",IF(G5=0,"Basis missing",IF(G5=11,"Not priced (at cost)",IF(NOT(ISNUMBER(H5)),"Rate missing",IF(AND(G5=9,NOT(ISNUMBER(Audit!$I$57))),"Base amount missing",IF(NOT(ISNUMBER(J5)),"Exchange rate missing",IF(NOT(ISNUMBER(P5)),"Calculated — Not Independently Verified",IF(ABS(R5)<=Lists!$B$44,"Verified","Error - differs by "&TEXT(R5,"#,##0.00")&" "&I5)))))))))))) | R5: =IF(AND(O5=1,ISNUMBER(P5)),IF(ABS(P5-L5)<=ABS(P5-M5),P5-L5,P5-M5),"") | S5: =IF(AND(O5=1,ISNUMBER(Audit!$M$57),ISNUMBER(J5)),IF(H5-Audit!$M$57>0.005,ROUND((H5-Audit!$M$57)*K5*(1+Y5)*J5,2),0),0) -> 0 | T5: =Audit!$N$57&"" | U5: =IF(B5="",0,IF(COUNTIFS($B$2:$B$51,B5,$D$2:$D$51,D5)>1,1,0)) -> 0 | V5: =IF(D5="","",IFERROR(INDEX(Audit!$C$43:$C$49,MATCH(D5,Lists!$A$30:$A$36,0)),"")) | W5: =IF(AND(B5<>"",OR(F5="At cost",F5="TBC",AND(F5<>"If required",G5=11))),1,0) -> 0 | X5: =IF(B5="","",IF(T5<>"","flag",IF(F5="","status",IF(AND(G5=0,OR(F5="Firm",F5="Estimate",AND(F5="If required",ISNUMBER(H5)))),"basis",IF(AND(OR(F5="Firm",F5="Estimate"),G5<>11,NOT(ISNUMBER(H5))),"rate",IF(AND(O5=0,G5=9,OR(F5="Firm",F5="Estimate"),ISNUMBER(H5)),"base",IF(OR(C5="",C5="Unclassified"),"unclass",IF(U5=1,"dup",IF(AND(Audit!$C$19="Yes",O5=1,NOT(ISNUMBER(Audit!$M$57))),"noagree",""))))))))) | Y5: =IF(ISNUMBER(Audit!$K$57),Audit!$K$57,0) -> 0 | Z5: =IF(AND(F5="Firm",O5=1,ISNUMBER(J5)),L5*J5,0) -> 0 | AE5: Risks | AF5: =SUMIFS($B$70:$B$470,$C$70:$C$470,"Risk") -> 0 | AH5: 4 | AI5: =IFERROR(SMALL($J$70:$J$470,AH5),"") | AJ5: =IF(AI5="","",MATCH(AI5,$J$70:$J$470,0)) | AL5: 4 | AM5: =IFERROR(SMALL($K$70:$K$470,AL5),"") | AN5: =IF(AM5="","",MATCH(AM5,$K$70:$K$470,0))
A6: 5 | B6: =TRIM(Audit!$B$58) | C6: =Audit!$C$58&"" | D6: =IF(B6="","",IF(C6="","Other",IFERROR(INDEX(Lists!$C$4:$C$16,MATCH(C6,Lists!$A$4:$A$16,0)),"Other"))) | E6: =IF(B6="","",IF(C6="","Other",IFERROR(INDEX(Lists!$B$4:$B$16,MATCH(C6,Lists!$A$4:$A$16,0)),"Other"))) | F6: =Audit!$G$58&"" | G6: =IFERROR(MATCH(Audit!$D$58,Lists!$E$4:$E$14,0),0) -> 0 | H6: =IF(ISNUMBER(Audit!$E$58),Audit!$E$58,"") | I6: =IF(TRIM(Audit!$F$58)="",Audit!$C$25,TRIM(Audit!$F$58)) -> 0 | J6: =IF(OR(I6=Audit!$C$25,I6=""),1,IF(AND(I6=Audit!$C$31,ISNUMBER(Audit!$J$31)),Audit!$J$31,IF(AND(I6=Audit!$C$32,ISNUMBER(Audit!$J$32)),Audit!$J$32,""))) -> 1 | K6: =IF(B6="","",IF(ISNUMBER(Audit!$I$58),Audit!$I$58,IF(G6=0,"",CHOOSE(G6,IF(ISNUMBER(Audit!$C$26),Audit!$C$26,1),1,1,1,$AF$33,$AF$30,$AF$31,1,"",1,0)))) | L6: =IF(O6=1,ROUND(MAX(H6*K6,IF(ISNUMBER(Audit!$J$58),Audit!$J$58,0)),2),"") | M6: =IF(O6=1,ROUND(L6*(1+Y6),2),"") | N6: =IF(O6=1,IF(ISNUMBER(J6),ROUND(M6*J6,2),""),"") | O6: =IF(AND(B6<>"",OR(F6="Firm",F6="Estimate",F6="If required"),ISNUMBER(H6),G6>0,G6<>11,ISNUMBER(K6)),1,0) -> 0 | P6: =IF(ISNUMBER(Audit!$L$58),Audit!$L$58,"") | Q6: =IF(B6="","",IF(OR(F6="At cost",F6="TBC"),"Not priced ("&F6&")",IF(OR(F6="Included",F6="Excluded",F6="Not applicable"),F6,IF(F6="","Status missing",IF(AND(F6="If required",NOT(ISNUMBER(H6))),"Not priced (if required)",IF(G6=0,"Basis missing",IF(G6=11,"Not priced (at cost)",IF(NOT(ISNUMBER(H6)),"Rate missing",IF(AND(G6=9,NOT(ISNUMBER(Audit!$I$58))),"Base amount missing",IF(NOT(ISNUMBER(J6)),"Exchange rate missing",IF(NOT(ISNUMBER(P6)),"Calculated — Not Independently Verified",IF(ABS(R6)<=Lists!$B$44,"Verified","Error - differs by "&TEXT(R6,"#,##0.00")&" "&I6)))))))))))) | R6: =IF(AND(O6=1,ISNUMBER(P6)),IF(ABS(P6-L6)<=ABS(P6-M6),P6-L6,P6-M6),"") | S6: =IF(AND(O6=1,ISNUMBER(Audit!$M$58),ISNUMBER(J6)),IF(H6-Audit!$M$58>0.005,ROUND((H6-Audit!$M$58)*K6*(1+Y6)*J6,2),0),0) -> 0 | T6: =Audit!$N$58&"" | U6: =IF(B6="",0,IF(COUNTIFS($B$2:$B$51,B6,$D$2:$D$51,D6)>1,1,0)) -> 0 | V6: =IF(D6="","",IFERROR(INDEX(Audit!$C$43:$C$49,MATCH(D6,Lists!$A$30:$A$36,0)),"")) | W6: =IF(AND(B6<>"",OR(F6="At cost",F6="TBC",AND(F6<>"If required",G6=11))),1,0) -> 0 | X6: =IF(B6="","",IF(T6<>"","flag",IF(F6="","status",IF(AND(G6=0,OR(F6="Firm",F6="Estimate",AND(F6="If required",ISNUMBER(H6)))),"basis",IF(AND(OR(F6="Firm",F6="Estimate"),G6<>11,NOT(ISNUMBER(H6))),"rate",IF(AND(O6=0,G6=9,OR(F6="Firm",F6="Estimate"),ISNUMBER(H6)),"base",IF(OR(C6="",C6="Unclassified"),"unclass",IF(U6=1,"dup",IF(AND(Audit!$C$19="Yes",O6=1,NOT(ISNUMBER(Audit!$M$58))),"noagree",""))))))))) | Y6: =IF(ISNUMBER(Audit!$K$58),Audit!$K$58,0) -> 0 | Z6: =IF(AND(F6="Firm",O6=1,ISNUMBER(J6)),L6*J6,0) -> 0 | AE6: Insufficient | AF6: =IF(OR(Audit!$C$18="No",Audit!$J$18="No",Audit!$J$19="No",AND(AF7>0,AF8=0)),1,0) -> 0 | AH6: 5 | AI6: =IFERROR(SMALL($J$70:$J$470,AH6),"") | AJ6: =IF(AI6="","",MATCH(AI6,$J$70:$J$470,0)) | AL6: 5 | AM6: =IFERROR(SMALL($K$70:$K$470,AL6),"") | AN6: =IF(AM6="","",MATCH(AM6,$K$70:$K$470,0))
A7: 6 | B7: =TRIM(Audit!$B$59) | C7: =Audit!$C$59&"" | D7: =IF(B7="","",IF(C7="","Other",IFERROR(INDEX(Lists!$C$4:$C$16,MATCH(C7,Lists!$A$4:$A$16,0)),"Other"))) | E7: =IF(B7="","",IF(C7="","Other",IFERROR(INDEX(Lists!$B$4:$B$16,MATCH(C7,Lists!$A$4:$A$16,0)),"Other"))) | F7: =Audit!$G$59&"" | G7: =IFERROR(MATCH(Audit!$D$59,Lists!$E$4:$E$14,0),0) -> 0 | H7: =IF(ISNUMBER(Audit!$E$59),Audit!$E$59,"") | I7: =IF(TRIM(Audit!$F$59)="",Audit!$C$25,TRIM(Audit!$F$59)) -> 0 | J7: =IF(OR(I7=Audit!$C$25,I7=""),1,IF(AND(I7=Audit!$C$31,ISNUMBER(Audit!$J$31)),Audit!$J$31,IF(AND(I7=Audit!$C$32,ISNUMBER(Audit!$J$32)),Audit!$J$32,""))) -> 1 | K7: =IF(B7="","",IF(ISNUMBER(Audit!$I$59),Audit!$I$59,IF(G7=0,"",CHOOSE(G7,IF(ISNUMBER(Audit!$C$26),Audit!$C$26,1),1,1,1,$AF$33,$AF$30,$AF$31,1,"",1,0)))) | L7: =IF(O7=1,ROUND(MAX(H7*K7,IF(ISNUMBER(Audit!$J$59),Audit!$J$59,0)),2),"") | M7: =IF(O7=1,ROUND(L7*(1+Y7),2),"") | N7: =IF(O7=1,IF(ISNUMBER(J7),ROUND(M7*J7,2),""),"") | O7: =IF(AND(B7<>"",OR(F7="Firm",F7="Estimate",F7="If required"),ISNUMBER(H7),G7>0,G7<>11,ISNUMBER(K7)),1,0) -> 0 | P7: =IF(ISNUMBER(Audit!$L$59),Audit!$L$59,"") | Q7: =IF(B7="","",IF(OR(F7="At cost",F7="TBC"),"Not priced ("&F7&")",IF(OR(F7="Included",F7="Excluded",F7="Not applicable"),F7,IF(F7="","Status missing",IF(AND(F7="If required",NOT(ISNUMBER(H7))),"Not priced (if required)",IF(G7=0,"Basis missing",IF(G7=11,"Not priced (at cost)",IF(NOT(ISNUMBER(H7)),"Rate missing",IF(AND(G7=9,NOT(ISNUMBER(Audit!$I$59))),"Base amount missing",IF(NOT(ISNUMBER(J7)),"Exchange rate missing",IF(NOT(ISNUMBER(P7)),"Calculated — Not Independently Verified",IF(ABS(R7)<=Lists!$B$44,"Verified","Error - differs by "&TEXT(R7,"#,##0.00")&" "&I7)))))))))))) | R7: =IF(AND(O7=1,ISNUMBER(P7)),IF(ABS(P7-L7)<=ABS(P7-M7),P7-L7,P7-M7),"") | S7: =IF(AND(O7=1,ISNUMBER(Audit!$M$59),ISNUMBER(J7)),IF(H7-Audit!$M$59>0.005,ROUND((H7-Audit!$M$59)*K7*(1+Y7)*J7,2),0),0) -> 0 | T7: =Audit!$N$59&"" | U7: =IF(B7="",0,IF(COUNTIFS($B$2:$B$51,B7,$D$2:$D$51,D7)>1,1,0)) -> 0 | V7: =IF(D7="","",IFERROR(INDEX(Audit!$C$43:$C$49,MATCH(D7,Lists!$A$30:$A$36,0)),"")) | W7: =IF(AND(B7<>"",OR(F7="At cost",F7="TBC",AND(F7<>"If required",G7=11))),1,0) -> 0 | X7: =IF(B7="","",IF(T7<>"","flag",IF(F7="","status",IF(AND(G7=0,OR(F7="Firm",F7="Estimate",AND(F7="If required",ISNUMBER(H7)))),"basis",IF(AND(OR(F7="Firm",F7="Estimate"),G7<>11,NOT(ISNUMBER(H7))),"rate",IF(AND(O7=0,G7=9,OR(F7="Firm",F7="Estimate"),ISNUMBER(H7)),"base",IF(OR(C7="",C7="Unclassified"),"unclass",IF(U7=1,"dup",IF(AND(Audit!$C$19="Yes",O7=1,NOT(ISNUMBER(Audit!$M$59))),"noagree",""))))))))) | Y7: =IF(ISNUMBER(Audit!$K$59),Audit!$K$59,0) -> 0 | Z7: =IF(AND(F7="Firm",O7=1,ISNUMBER(J7)),L7*J7,0) -> 0 | AE7: Lines entered | AF7: =COUNTIF($B$2:$B$51,"?*") -> 0 | AH7: 6 | AI7: =IFERROR(SMALL($J$70:$J$470,AH7),"") | AJ7: =IF(AI7="","",MATCH(AI7,$J$70:$J$470,0)) | AL7: 6 | AM7: =IFERROR(SMALL($K$70:$K$470,AL7),"") | AN7: =IF(AM7="","",MATCH(AM7,$K$70:$K$470,0))
A8: 7 | B8: =TRIM(Audit!$B$60) | C8: =Audit!$C$60&"" | D8: =IF(B8="","",IF(C8="","Other",IFERROR(INDEX(Lists!$C$4:$C$16,MATCH(C8,Lists!$A$4:$A$16,0)),"Other"))) | E8: =IF(B8="","",IF(C8="","Other",IFERROR(INDEX(Lists!$B$4:$B$16,MATCH(C8,Lists!$A$4:$A$16,0)),"Other"))) | F8: =Audit!$G$60&"" | G8: =IFERROR(MATCH(Audit!$D$60,Lists!$E$4:$E$14,0),0) -> 0 | H8: =IF(ISNUMBER(Audit!$E$60),Audit!$E$60,"") | I8: =IF(TRIM(Audit!$F$60)="",Audit!$C$25,TRIM(Audit!$F$60)) -> 0 | J8: =IF(OR(I8=Audit!$C$25,I8=""),1,IF(AND(I8=Audit!$C$31,ISNUMBER(Audit!$J$31)),Audit!$J$31,IF(AND(I8=Audit!$C$32,ISNUMBER(Audit!$J$32)),Audit!$J$32,""))) -> 1 | K8: =IF(B8="","",IF(ISNUMBER(Audit!$I$60),Audit!$I$60,IF(G8=0,"",CHOOSE(G8,IF(ISNUMBER(Audit!$C$26),Audit!$C$26,1),1,1,1,$AF$33,$AF$30,$AF$31,1,"",1,0)))) | L8: =IF(O8=1,ROUND(MAX(H8*K8,IF(ISNUMBER(Audit!$J$60),Audit!$J$60,0)),2),"") | M8: =IF(O8=1,ROUND(L8*(1+Y8),2),"") | N8: =IF(O8=1,IF(ISNUMBER(J8),ROUND(M8*J8,2),""),"") | O8: =IF(AND(B8<>"",OR(F8="Firm",F8="Estimate",F8="If required"),ISNUMBER(H8),G8>0,G8<>11,ISNUMBER(K8)),1,0) -> 0 | P8: =IF(ISNUMBER(Audit!$L$60),Audit!$L$60,"") | Q8: =IF(B8="","",IF(OR(F8="At cost",F8="TBC"),"Not priced ("&F8&")",IF(OR(F8="Included",F8="Excluded",F8="Not applicable"),F8,IF(F8="","Status missing",IF(AND(F8="If required",NOT(ISNUMBER(H8))),"Not priced (if required)",IF(G8=0,"Basis missing",IF(G8=11,"Not priced (at cost)",IF(NOT(ISNUMBER(H8)),"Rate missing",IF(AND(G8=9,NOT(ISNUMBER(Audit!$I$60))),"Base amount missing",IF(NOT(ISNUMBER(J8)),"Exchange rate missing",IF(NOT(ISNUMBER(P8)),"Calculated — Not Independently Verified",IF(ABS(R8)<=Lists!$B$44,"Verified","Error - differs by "&TEXT(R8,"#,##0.00")&" "&I8)))))))))))) | R8: =IF(AND(O8=1,ISNUMBER(P8)),IF(ABS(P8-L8)<=ABS(P8-M8),P8-L8,P8-M8),"") | S8: =IF(AND(O8=1,ISNUMBER(Audit!$M$60),ISNUMBER(J8)),IF(H8-Audit!$M$60>0.005,ROUND((H8-Audit!$M$60)*K8*(1+Y8)*J8,2),0),0) -> 0 | T8: =Audit!$N$60&"" | U8: =IF(B8="",0,IF(COUNTIFS($B$2:$B$51,B8,$D$2:$D$51,D8)>1,1,0)) -> 0 | V8: =IF(D8="","",IFERROR(INDEX(Audit!$C$43:$C$49,MATCH(D8,Lists!$A$30:$A$36,0)),"")) | W8: =IF(AND(B8<>"",OR(F8="At cost",F8="TBC",AND(F8<>"If required",G8=11))),1,0) -> 0 | X8: =IF(B8="","",IF(T8<>"","flag",IF(F8="","status",IF(AND(G8=0,OR(F8="Firm",F8="Estimate",AND(F8="If required",ISNUMBER(H8)))),"basis",IF(AND(OR(F8="Firm",F8="Estimate"),G8<>11,NOT(ISNUMBER(H8))),"rate",IF(AND(O8=0,G8=9,OR(F8="Firm",F8="Estimate"),ISNUMBER(H8)),"base",IF(OR(C8="",C8="Unclassified"),"unclass",IF(U8=1,"dup",IF(AND(Audit!$C$19="Yes",O8=1,NOT(ISNUMBER(Audit!$M$60))),"noagree",""))))))))) | Y8: =IF(ISNUMBER(Audit!$K$60),Audit!$K$60,0) -> 0 | Z8: =IF(AND(F8="Firm",O8=1,ISNUMBER(J8)),L8*J8,0) -> 0 | AE8: Priced lines | AF8: =SUM($O$2:$O$51) -> 0 | AH8: 7 | AI8: =IFERROR(SMALL($J$70:$J$470,AH8),"") | AJ8: =IF(AI8="","",MATCH(AI8,$J$70:$J$470,0)) | AL8: 7 | AM8: =IFERROR(SMALL($K$70:$K$470,AL8),"") | AN8: =IF(AM8="","",MATCH(AM8,$K$70:$K$470,0))
A9: 8 | B9: =TRIM(Audit!$B$61) | C9: =Audit!$C$61&"" | D9: =IF(B9="","",IF(C9="","Other",IFERROR(INDEX(Lists!$C$4:$C$16,MATCH(C9,Lists!$A$4:$A$16,0)),"Other"))) | E9: =IF(B9="","",IF(C9="","Other",IFERROR(INDEX(Lists!$B$4:$B$16,MATCH(C9,Lists!$A$4:$A$16,0)),"Other"))) | F9: =Audit!$G$61&"" | G9: =IFERROR(MATCH(Audit!$D$61,Lists!$E$4:$E$14,0),0) -> 0 | H9: =IF(ISNUMBER(Audit!$E$61),Audit!$E$61,"") | I9: =IF(TRIM(Audit!$F$61)="",Audit!$C$25,TRIM(Audit!$F$61)) -> 0 | J9: =IF(OR(I9=Audit!$C$25,I9=""),1,IF(AND(I9=Audit!$C$31,ISNUMBER(Audit!$J$31)),Audit!$J$31,IF(AND(I9=Audit!$C$32,ISNUMBER(Audit!$J$32)),Audit!$J$32,""))) -> 1 | K9: =IF(B9="","",IF(ISNUMBER(Audit!$I$61),Audit!$I$61,IF(G9=0,"",CHOOSE(G9,IF(ISNUMBER(Audit!$C$26),Audit!$C$26,1),1,1,1,$AF$33,$AF$30,$AF$31,1,"",1,0)))) | L9: =IF(O9=1,ROUND(MAX(H9*K9,IF(ISNUMBER(Audit!$J$61),Audit!$J$61,0)),2),"") | M9: =IF(O9=1,ROUND(L9*(1+Y9),2),"") | N9: =IF(O9=1,IF(ISNUMBER(J9),ROUND(M9*J9,2),""),"") | O9: =IF(AND(B9<>"",OR(F9="Firm",F9="Estimate",F9="If required"),ISNUMBER(H9),G9>0,G9<>11,ISNUMBER(K9)),1,0) -> 0 | P9: =IF(ISNUMBER(Audit!$L$61),Audit!$L$61,"") | Q9: =IF(B9="","",IF(OR(F9="At cost",F9="TBC"),"Not priced ("&F9&")",IF(OR(F9="Included",F9="Excluded",F9="Not applicable"),F9,IF(F9="","Status missing",IF(AND(F9="If required",NOT(ISNUMBER(H9))),"Not priced (if required)",IF(G9=0,"Basis missing",IF(G9=11,"Not priced (at cost)",IF(NOT(ISNUMBER(H9)),"Rate missing",IF(AND(G9=9,NOT(ISNUMBER(Audit!$I$61))),"Base amount missing",IF(NOT(ISNUMBER(J9)),"Exchange rate missing",IF(NOT(ISNUMBER(P9)),"Calculated — Not Independently Verified",IF(ABS(R9)<=Lists!$B$44,"Verified","Error - differs by "&TEXT(R9,"#,##0.00")&" "&I9)))))))))))) | R9: =IF(AND(O9=1,ISNUMBER(P9)),IF(ABS(P9-L9)<=ABS(P9-M9),P9-L9,P9-M9),"") | S9: =IF(AND(O9=1,ISNUMBER(Audit!$M$61),ISNUMBER(J9)),IF(H9-Audit!$M$61>0.005,ROUND((H9-Audit!$M$61)*K9*(1+Y9)*J9,2),0),0) -> 0 | T9: =Audit!$N$61&"" | U9: =IF(B9="",0,IF(COUNTIFS($B$2:$B$51,B9,$D$2:$D$51,D9)>1,1,0)) -> 0 | V9: =IF(D9="","",IFERROR(INDEX(Audit!$C$43:$C$49,MATCH(D9,Lists!$A$30:$A$36,0)),"")) | W9: =IF(AND(B9<>"",OR(F9="At cost",F9="TBC",AND(F9<>"If required",G9=11))),1,0) -> 0 | X9: =IF(B9="","",IF(T9<>"","flag",IF(F9="","status",IF(AND(G9=0,OR(F9="Firm",F9="Estimate",AND(F9="If required",ISNUMBER(H9)))),"basis",IF(AND(OR(F9="Firm",F9="Estimate"),G9<>11,NOT(ISNUMBER(H9))),"rate",IF(AND(O9=0,G9=9,OR(F9="Firm",F9="Estimate"),ISNUMBER(H9)),"base",IF(OR(C9="",C9="Unclassified"),"unclass",IF(U9=1,"dup",IF(AND(Audit!$C$19="Yes",O9=1,NOT(ISNUMBER(Audit!$M$61))),"noagree",""))))))))) | Y9: =IF(ISNUMBER(Audit!$K$61),Audit!$K$61,0) -> 0 | Z9: =IF(AND(F9="Firm",O9=1,ISNUMBER(J9)),L9*J9,0) -> 0 | AE9: FX missing | AF9: =COUNTIFS($Q$2:$Q$51,"Exchange rate missing") -> 0 | AH9: 8 | AI9: =IFERROR(SMALL($J$70:$J$470,AH9),"") | AJ9: =IF(AI9="","",MATCH(AI9,$J$70:$J$470,0)) | AL9: 8 | AM9: =IFERROR(SMALL($K$70:$K$470,AL9),"") | AN9: =IF(AM9="","",MATCH(AM9,$K$70:$K$470,0))
A10: 9 | B10: =TRIM(Audit!$B$62) | C10: =Audit!$C$62&"" | D10: =IF(B10="","",IF(C10="","Other",IFERROR(INDEX(Lists!$C$4:$C$16,MATCH(C10,Lists!$A$4:$A$16,0)),"Other"))) | E10: =IF(B10="","",IF(C10="","Other",IFERROR(INDEX(Lists!$B$4:$B$16,MATCH(C10,Lists!$A$4:$A$16,0)),"Other"))) | F10: =Audit!$G$62&"" | G10: =IFERROR(MATCH(Audit!$D$62,Lists!$E$4:$E$14,0),0) -> 0 | H10: =IF(ISNUMBER(Audit!$E$62),Audit!$E$62,"") | I10: =IF(TRIM(Audit!$F$62)="",Audit!$C$25,TRIM(Audit!$F$62)) -> 0 | J10: =IF(OR(I10=Audit!$C$25,I10=""),1,IF(AND(I10=Audit!$C$31,ISNUMBER(Audit!$J$31)),Audit!$J$31,IF(AND(I10=Audit!$C$32,ISNUMBER(Audit!$J$32)),Audit!$J$32,""))) -> 1 | K10: =IF(B10="","",IF(ISNUMBER(Audit!$I$62),Audit!$I$62,IF(G10=0,"",CHOOSE(G10,IF(ISNUMBER(Audit!$C$26),Audit!$C$26,1),1,1,1,$AF$33,$AF$30,$AF$31,1,"",1,0)))) | L10: =IF(O10=1,ROUND(MAX(H10*K10,IF(ISNUMBER(Audit!$J$62),Audit!$J$62,0)),2),"") | M10: =IF(O10=1,ROUND(L10*(1+Y10),2),"") | N10: =IF(O10=1,IF(ISNUMBER(J10),ROUND(M10*J10,2),""),"") | O10: =IF(AND(B10<>"",OR(F10="Firm",F10="Estimate",F10="If required"),ISNUMBER(H10),G10>0,G10<>11,ISNUMBER(K10)),1,0) -> 0 | P10: =IF(ISNUMBER(Audit!$L$62),Audit!$L$62,"") | Q10: =IF(B10="","",IF(OR(F10="At cost",F10="TBC"),"Not priced ("&F10&")",IF(OR(F10="Included",F10="Excluded",F10="Not applicable"),F10,IF(F10="","Status missing",IF(AND(F10="If required",NOT(ISNUMBER(H10))),"Not priced (if required)",IF(G10=0,"Basis missing",IF(G10=11,"Not priced (at cost)",IF(NOT(ISNUMBER(H10)),"Rate missing",IF(AND(G10=9,NOT(ISNUMBER(Audit!$I$62))),"Base amount missing",IF(NOT(ISNUMBER(J10)),"Exchange rate missing",IF(NOT(ISNUMBER(P10)),"Calculated — Not Independently Verified",IF(ABS(R10)<=Lists!$B$44,"Verified","Error - differs by "&TEXT(R10,"#,##0.00")&" "&I10)))))))))))) | R10: =IF(AND(O10=1,ISNUMBER(P10)),IF(ABS(P10-L10)<=ABS(P10-M10),P10-L10,P10-M10),"") | S10: =IF(AND(O10=1,ISNUMBER(Audit!$M$62),ISNUMBER(J10)),IF(H10-Audit!$M$62>0.005,ROUND((H10-Audit!$M$62)*K10*(1+Y10)*J10,2),0),0) -> 0 | T10: =Audit!$N$62&"" | U10: =IF(B10="",0,IF(COUNTIFS($B$2:$B$51,B10,$D$2:$D$51,D10)>1,1,0)) -> 0 | V10: =IF(D10="","",IFERROR(INDEX(Audit!$C$43:$C$49,MATCH(D10,Lists!$A$30:$A$36,0)),"")) | W10: =IF(AND(B10<>"",OR(F10="At cost",F10="TBC",AND(F10<>"If required",G10=11))),1,0) -> 0 | X10: =IF(B10="","",IF(T10<>"","flag",IF(F10="","status",IF(AND(G10=0,OR(F10="Firm",F10="Estimate",AND(F10="If required",ISNUMBER(H10)))),"basis",IF(AND(OR(F10="Firm",F10="Estimate"),G10<>11,NOT(ISNUMBER(H10))),"rate",IF(AND(O10=0,G10=9,OR(F10="Firm",F10="Estimate"),ISNUMBER(H10)),"base",IF(OR(C10="",C10="Unclassified"),"unclass",IF(U10=1,"dup",IF(AND(Audit!$C$19="Yes",O10=1,NOT(ISNUMBER(Audit!$M$62))),"noagree",""))))))))) | Y10: =IF(ISNUMBER(Audit!$K$62),Audit!$K$62,0) -> 0 | Z10: =IF(AND(F10="Firm",O10=1,ISNUMBER(J10)),L10*J10,0) -> 0 | AE10: Known firm (quote cur) | AF10: =SUMIFS($N$2:$N$51,$F$2:$F$51,"Firm") -> 0 | AH10: 9 | AI10: =IFERROR(SMALL($J$70:$J$470,AH10),"") | AJ10: =IF(AI10="","",MATCH(AI10,$J$70:$J$470,0)) | AL10: 9 | AM10: =IFERROR(SMALL($K$70:$K$470,AL10),"") | AN10: =IF(AM10="","",MATCH(AM10,$K$70:$K$470,0))
A11: 10 | B11: =TRIM(Audit!$B$63) | C11: =Audit!$C$63&"" | D11: =IF(B11="","",IF(C11="","Other",IFERROR(INDEX(Lists!$C$4:$C$16,MATCH(C11,Lists!$A$4:$A$16,0)),"Other"))) | E11: =IF(B11="","",IF(C11="","Other",IFERROR(INDEX(Lists!$B$4:$B$16,MATCH(C11,Lists!$A$4:$A$16,0)),"Other"))) | F11: =Audit!$G$63&"" | G11: =IFERROR(MATCH(Audit!$D$63,Lists!$E$4:$E$14,0),0) -> 0 | H11: =IF(ISNUMBER(Audit!$E$63),Audit!$E$63,"") | I11: =IF(TRIM(Audit!$F$63)="",Audit!$C$25,TRIM(Audit!$F$63)) -> 0 | J11: =IF(OR(I11=Audit!$C$25,I11=""),1,IF(AND(I11=Audit!$C$31,ISNUMBER(Audit!$J$31)),Audit!$J$31,IF(AND(I11=Audit!$C$32,ISNUMBER(Audit!$J$32)),Audit!$J$32,""))) -> 1 | K11: =IF(B11="","",IF(ISNUMBER(Audit!$I$63),Audit!$I$63,IF(G11=0,"",CHOOSE(G11,IF(ISNUMBER(Audit!$C$26),Audit!$C$26,1),1,1,1,$AF$33,$AF$30,$AF$31,1,"",1,0)))) | L11: =IF(O11=1,ROUND(MAX(H11*K11,IF(ISNUMBER(Audit!$J$63),Audit!$J$63,0)),2),"") | M11: =IF(O11=1,ROUND(L11*(1+Y11),2),"") | N11: =IF(O11=1,IF(ISNUMBER(J11),ROUND(M11*J11,2),""),"") | O11: =IF(AND(B11<>"",OR(F11="Firm",F11="Estimate",F11="If required"),ISNUMBER(H11),G11>0,G11<>11,ISNUMBER(K11)),1,0) -> 0 | P11: =IF(ISNUMBER(Audit!$L$63),Audit!$L$63,"") | Q11: =IF(B11="","",IF(OR(F11="At cost",F11="TBC"),"Not priced ("&F11&")",IF(OR(F11="Included",F11="Excluded",F11="Not applicable"),F11,IF(F11="","Status missing",IF(AND(F11="If required",NOT(ISNUMBER(H11))),"Not priced (if required)",IF(G11=0,"Basis missing",IF(G11=11,"Not priced (at cost)",IF(NOT(ISNUMBER(H11)),"Rate missing",IF(AND(G11=9,NOT(ISNUMBER(Audit!$I$63))),"Base amount missing",IF(NOT(ISNUMBER(J11)),"Exchange rate missing",IF(NOT(ISNUMBER(P11)),"Calculated — Not Independently Verified",IF(ABS(R11)<=Lists!$B$44,"Verified","Error - differs by "&TEXT(R11,"#,##0.00")&" "&I11)))))))))))) | R11: =IF(AND(O11=1,ISNUMBER(P11)),IF(ABS(P11-L11)<=ABS(P11-M11),P11-L11,P11-M11),"") | S11: =IF(AND(O11=1,ISNUMBER(Audit!$M$63),ISNUMBER(J11)),IF(H11-Audit!$M$63>0.005,ROUND((H11-Audit!$M$63)*K11*(1+Y11)*J11,2),0),0) -> 0 | T11: =Audit!$N$63&"" | U11: =IF(B11="",0,IF(COUNTIFS($B$2:$B$51,B11,$D$2:$D$51,D11)>1,1,0)) -> 0 | V11: =IF(D11="","",IFERROR(INDEX(Audit!$C$43:$C$49,MATCH(D11,Lists!$A$30:$A$36,0)),"")) | W11: =IF(AND(B11<>"",OR(F11="At cost",F11="TBC",AND(F11<>"If required",G11=11))),1,0) -> 0 | X11: =IF(B11="","",IF(T11<>"","flag",IF(F11="","status",IF(AND(G11=0,OR(F11="Firm",F11="Estimate",AND(F11="If required",ISNUMBER(H11)))),"basis",IF(AND(OR(F11="Firm",F11="Estimate"),G11<>11,NOT(ISNUMBER(H11))),"rate",IF(AND(O11=0,G11=9,OR(F11="Firm",F11="Estimate"),ISNUMBER(H11)),"base",IF(OR(C11="",C11="Unclassified"),"unclass",IF(U11=1,"dup",IF(AND(Audit!$C$19="Yes",O11=1,NOT(ISNUMBER(Audit!$M$63))),"noagree",""))))))))) | Y11: =IF(ISNUMBER(Audit!$K$63),Audit!$K$63,0) -> 0 | Z11: =IF(AND(F11="Firm",O11=1,ISNUMBER(J11)),L11*J11,0) -> 0 | AE11: Estimates | AF11: =SUMIFS($N$2:$N$51,$F$2:$F$51,"Estimate") -> 0 | AH11: 10 | AI11: =IFERROR(SMALL($J$70:$J$470,AH11),"") | AJ11: =IF(AI11="","",MATCH(AI11,$J$70:$J$470,0)) | AL11: 10 | AM11: =IFERROR(SMALL($K$70:$K$470,AL11),"") | AN11: =IF(AM11="","",MATCH(AM11,$K$70:$K$470,0))
A12: 11 | B12: =TRIM(Audit!$B$64) | C12: =Audit!$C$64&"" | D12: =IF(B12="","",IF(C12="","Other",IFERROR(INDEX(Lists!$C$4:$C$16,MATCH(C12,Lists!$A$4:$A$16,0)),"Other"))) | E12: =IF(B12="","",IF(C12="","Other",IFERROR(INDEX(Lists!$B$4:$B$16,MATCH(C12,Lists!$A$4:$A$16,0)),"Other"))) | F12: =Audit!$G$64&"" | G12: =IFERROR(MATCH(Audit!$D$64,Lists!$E$4:$E$14,0),0) -> 0 | H12: =IF(ISNUMBER(Audit!$E$64),Audit!$E$64,"") | I12: =IF(TRIM(Audit!$F$64)="",Audit!$C$25,TRIM(Audit!$F$64)) -> 0 | J12: =IF(OR(I12=Audit!$C$25,I12=""),1,IF(AND(I12=Audit!$C$31,ISNUMBER(Audit!$J$31)),Audit!$J$31,IF(AND(I12=Audit!$C$32,ISNUMBER(Audit!$J$32)),Audit!$J$32,""))) -> 1 | K12: =IF(B12="","",IF(ISNUMBER(Audit!$I$64),Audit!$I$64,IF(G12=0,"",CHOOSE(G12,IF(ISNUMBER(Audit!$C$26),Audit!$C$26,1),1,1,1,$AF$33,$AF$30,$AF$31,1,"",1,0)))) | L12: =IF(O12=1,ROUND(MAX(H12*K12,IF(ISNUMBER(Audit!$J$64),Audit!$J$64,0)),2),"") | M12: =IF(O12=1,ROUND(L12*(1+Y12),2),"") | N12: =IF(O12=1,IF(ISNUMBER(J12),ROUND(M12*J12,2),""),"") | O12: =IF(AND(B12<>"",OR(F12="Firm",F12="Estimate",F12="If required"),ISNUMBER(H12),G12>0,G12<>11,ISNUMBER(K12)),1,0) -> 0 | P12: =IF(ISNUMBER(Audit!$L$64),Audit!$L$64,"") | Q12: =IF(B12="","",IF(OR(F12="At cost",F12="TBC"),"Not priced ("&F12&")",IF(OR(F12="Included",F12="Excluded",F12="Not applicable"),F12,IF(F12="","Status missing",IF(AND(F12="If required",NOT(ISNUMBER(H12))),"Not priced (if required)",IF(G12=0,"Basis missing",IF(G12=11,"Not priced (at cost)",IF(NOT(ISNUMBER(H12)),"Rate missing",IF(AND(G12=9,NOT(ISNUMBER(Audit!$I$64))),"Base amount missing",IF(NOT(ISNUMBER(J12)),"Exchange rate missing",IF(NOT(ISNUMBER(P12)),"Calculated — Not Independently Verified",IF(ABS(R12)<=Lists!$B$44,"Verified","Error - differs by "&TEXT(R12,"#,##0.00")&" "&I12)))))))))))) | R12: =IF(AND(O12=1,ISNUMBER(P12)),IF(ABS(P12-L12)<=ABS(P12-M12),P12-L12,P12-M12),"") | S12: =IF(AND(O12=1,ISNUMBER(Audit!$M$64),ISNUMBER(J12)),IF(H12-Audit!$M$64>0.005,ROUND((H12-Audit!$M$64)*K12*(1+Y12)*J12,2),0),0) -> 0 | T12: =Audit!$N$64&"" | U12: =IF(B12="",0,IF(COUNTIFS($B$2:$B$51,B12,$D$2:$D$51,D12)>1,1,0)) -> 0 | V12: =IF(D12="","",IFERROR(INDEX(Audit!$C$43:$C$49,MATCH(D12,Lists!$A$30:$A$36,0)),"")) | W12: =IF(AND(B12<>"",OR(F12="At cost",F12="TBC",AND(F12<>"If required",G12=11))),1,0) -> 0 | X12: =IF(B12="","",IF(T12<>"","flag",IF(F12="","status",IF(AND(G12=0,OR(F12="Firm",F12="Estimate",AND(F12="If required",ISNUMBER(H12)))),"basis",IF(AND(OR(F12="Firm",F12="Estimate"),G12<>11,NOT(ISNUMBER(H12))),"rate",IF(AND(O12=0,G12=9,OR(F12="Firm",F12="Estimate"),ISNUMBER(H12)),"base",IF(OR(C12="",C12="Unclassified"),"unclass",IF(U12=1,"dup",IF(AND(Audit!$C$19="Yes",O12=1,NOT(ISNUMBER(Audit!$M$64))),"noagree",""))))))))) | Y12: =IF(ISNUMBER(Audit!$K$64),Audit!$K$64,0) -> 0 | Z12: =IF(AND(F12="Firm",O12=1,ISNUMBER(J12)),L12*J12,0) -> 0 | AE12: Estimate lines | AF12: =COUNTIFS($F$2:$F$51,"Estimate") -> 0 | AH12: 11 | AI12: =IFERROR(SMALL($J$70:$J$470,AH12),"") | AJ12: =IF(AI12="","",MATCH(AI12,$J$70:$J$470,0)) | AL12: 11 | AM12: =IFERROR(SMALL($K$70:$K$470,AL12),"") | AN12: =IF(AM12="","",MATCH(AM12,$K$70:$K$470,0))
A13: 12 | B13: =TRIM(Audit!$B$65) | C13: =Audit!$C$65&"" | D13: =IF(B13="","",IF(C13="","Other",IFERROR(INDEX(Lists!$C$4:$C$16,MATCH(C13,Lists!$A$4:$A$16,0)),"Other"))) | E13: =IF(B13="","",IF(C13="","Other",IFERROR(INDEX(Lists!$B$4:$B$16,MATCH(C13,Lists!$A$4:$A$16,0)),"Other"))) | F13: =Audit!$G$65&"" | G13: =IFERROR(MATCH(Audit!$D$65,Lists!$E$4:$E$14,0),0) -> 0 | H13: =IF(ISNUMBER(Audit!$E$65),Audit!$E$65,"") | I13: =IF(TRIM(Audit!$F$65)="",Audit!$C$25,TRIM(Audit!$F$65)) -> 0 | J13: =IF(OR(I13=Audit!$C$25,I13=""),1,IF(AND(I13=Audit!$C$31,ISNUMBER(Audit!$J$31)),Audit!$J$31,IF(AND(I13=Audit!$C$32,ISNUMBER(Audit!$J$32)),Audit!$J$32,""))) -> 1 | K13: =IF(B13="","",IF(ISNUMBER(Audit!$I$65),Audit!$I$65,IF(G13=0,"",CHOOSE(G13,IF(ISNUMBER(Audit!$C$26),Audit!$C$26,1),1,1,1,$AF$33,$AF$30,$AF$31,1,"",1,0)))) | L13: =IF(O13=1,ROUND(MAX(H13*K13,IF(ISNUMBER(Audit!$J$65),Audit!$J$65,0)),2),"") | M13: =IF(O13=1,ROUND(L13*(1+Y13),2),"") | N13: =IF(O13=1,IF(ISNUMBER(J13),ROUND(M13*J13,2),""),"") | O13: =IF(AND(B13<>"",OR(F13="Firm",F13="Estimate",F13="If required"),ISNUMBER(H13),G13>0,G13<>11,ISNUMBER(K13)),1,0) -> 0 | P13: =IF(ISNUMBER(Audit!$L$65),Audit!$L$65,"") | Q13: =IF(B13="","",IF(OR(F13="At cost",F13="TBC"),"Not priced ("&F13&")",IF(OR(F13="Included",F13="Excluded",F13="Not applicable"),F13,IF(F13="","Status missing",IF(AND(F13="If required",NOT(ISNUMBER(H13))),"Not priced (if required)",IF(G13=0,"Basis missing",IF(G13=11,"Not priced (at cost)",IF(NOT(ISNUMBER(H13)),"Rate missing",IF(AND(G13=9,NOT(ISNUMBER(Audit!$I$65))),"Base amount missing",IF(NOT(ISNUMBER(J13)),"Exchange rate missing",IF(NOT(ISNUMBER(P13)),"Calculated — Not Independently Verified",IF(ABS(R13)<=Lists!$B$44,"Verified","Error - differs by "&TEXT(R13,"#,##0.00")&" "&I13)))))))))))) | R13: =IF(AND(O13=1,ISNUMBER(P13)),IF(ABS(P13-L13)<=ABS(P13-M13),P13-L13,P13-M13),"") | S13: =IF(AND(O13=1,ISNUMBER(Audit!$M$65),ISNUMBER(J13)),IF(H13-Audit!$M$65>0.005,ROUND((H13-Audit!$M$65)*K13*(1+Y13)*J13,2),0),0) -> 0 | T13: =Audit!$N$65&"" | U13: =IF(B13="",0,IF(COUNTIFS($B$2:$B$51,B13,$D$2:$D$51,D13)>1,1,0)) -> 0 | V13: =IF(D13="","",IFERROR(INDEX(Audit!$C$43:$C$49,MATCH(D13,Lists!$A$30:$A$36,0)),"")) | W13: =IF(AND(B13<>"",OR(F13="At cost",F13="TBC",AND(F13<>"If required",G13=11))),1,0) -> 0 | X13: =IF(B13="","",IF(T13<>"","flag",IF(F13="","status",IF(AND(G13=0,OR(F13="Firm",F13="Estimate",AND(F13="If required",ISNUMBER(H13)))),"basis",IF(AND(OR(F13="Firm",F13="Estimate"),G13<>11,NOT(ISNUMBER(H13))),"rate",IF(AND(O13=0,G13=9,OR(F13="Firm",F13="Estimate"),ISNUMBER(H13)),"base",IF(OR(C13="",C13="Unclassified"),"unclass",IF(U13=1,"dup",IF(AND(Audit!$C$19="Yes",O13=1,NOT(ISNUMBER(Audit!$M$65))),"noagree",""))))))))) | Y13: =IF(ISNUMBER(Audit!$K$65),Audit!$K$65,0) -> 0 | Z13: =IF(AND(F13="Firm",O13=1,ISNUMBER(J13)),L13*J13,0) -> 0 | AE13: Conditional priced | AF13: =SUMIFS($N$2:$N$51,$F$2:$F$51,"If required") -> 0 | AH13: 12 | AI13: =IFERROR(SMALL($J$70:$J$470,AH13),"") | AJ13: =IF(AI13="","",MATCH(AI13,$J$70:$J$470,0)) | AL13: 12 | AM13: =IFERROR(SMALL($K$70:$K$470,AL13),"") | AN13: =IF(AM13="","",MATCH(AM13,$K$70:$K$470,0))
A14: 13 | B14: =TRIM(Audit!$B$66) | C14: =Audit!$C$66&"" | D14: =IF(B14="","",IF(C14="","Other",IFERROR(INDEX(Lists!$C$4:$C$16,MATCH(C14,Lists!$A$4:$A$16,0)),"Other"))) | E14: =IF(B14="","",IF(C14="","Other",IFERROR(INDEX(Lists!$B$4:$B$16,MATCH(C14,Lists!$A$4:$A$16,0)),"Other"))) | F14: =Audit!$G$66&"" | G14: =IFERROR(MATCH(Audit!$D$66,Lists!$E$4:$E$14,0),0) -> 0 | H14: =IF(ISNUMBER(Audit!$E$66),Audit!$E$66,"") | I14: =IF(TRIM(Audit!$F$66)="",Audit!$C$25,TRIM(Audit!$F$66)) -> 0 | J14: =IF(OR(I14=Audit!$C$25,I14=""),1,IF(AND(I14=Audit!$C$31,ISNUMBER(Audit!$J$31)),Audit!$J$31,IF(AND(I14=Audit!$C$32,ISNUMBER(Audit!$J$32)),Audit!$J$32,""))) -> 1 | K14: =IF(B14="","",IF(ISNUMBER(Audit!$I$66),Audit!$I$66,IF(G14=0,"",CHOOSE(G14,IF(ISNUMBER(Audit!$C$26),Audit!$C$26,1),1,1,1,$AF$33,$AF$30,$AF$31,1,"",1,0)))) | L14: =IF(O14=1,ROUND(MAX(H14*K14,IF(ISNUMBER(Audit!$J$66),Audit!$J$66,0)),2),"") | M14: =IF(O14=1,ROUND(L14*(1+Y14),2),"") | N14: =IF(O14=1,IF(ISNUMBER(J14),ROUND(M14*J14,2),""),"") | O14: =IF(AND(B14<>"",OR(F14="Firm",F14="Estimate",F14="If required"),ISNUMBER(H14),G14>0,G14<>11,ISNUMBER(K14)),1,0) -> 0 | P14: =IF(ISNUMBER(Audit!$L$66),Audit!$L$66,"") | Q14: =IF(B14="","",IF(OR(F14="At cost",F14="TBC"),"Not priced ("&F14&")",IF(OR(F14="Included",F14="Excluded",F14="Not applicable"),F14,IF(F14="","Status missing",IF(AND(F14="If required",NOT(ISNUMBER(H14))),"Not priced (if required)",IF(G14=0,"Basis missing",IF(G14=11,"Not priced (at cost)",IF(NOT(ISNUMBER(H14)),"Rate missing",IF(AND(G14=9,NOT(ISNUMBER(Audit!$I$66))),"Base amount missing",IF(NOT(ISNUMBER(J14)),"Exchange rate missing",IF(NOT(ISNUMBER(P14)),"Calculated — Not Independently Verified",IF(ABS(R14)<=Lists!$B$44,"Verified","Error - differs by "&TEXT(R14,"#,##0.00")&" "&I14)))))))))))) | R14: =IF(AND(O14=1,ISNUMBER(P14)),IF(ABS(P14-L14)<=ABS(P14-M14),P14-L14,P14-M14),"") | S14: =IF(AND(O14=1,ISNUMBER(Audit!$M$66),ISNUMBER(J14)),IF(H14-Audit!$M$66>0.005,ROUND((H14-Audit!$M$66)*K14*(1+Y14)*J14,2),0),0) -> 0 | T14: =Audit!$N$66&"" | U14: =IF(B14="",0,IF(COUNTIFS($B$2:$B$51,B14,$D$2:$D$51,D14)>1,1,0)) -> 0 | V14: =IF(D14="","",IFERROR(INDEX(Audit!$C$43:$C$49,MATCH(D14,Lists!$A$30:$A$36,0)),"")) | W14: =IF(AND(B14<>"",OR(F14="At cost",F14="TBC",AND(F14<>"If required",G14=11))),1,0) -> 0 | X14: =IF(B14="","",IF(T14<>"","flag",IF(F14="","status",IF(AND(G14=0,OR(F14="Firm",F14="Estimate",AND(F14="If required",ISNUMBER(H14)))),"basis",IF(AND(OR(F14="Firm",F14="Estimate"),G14<>11,NOT(ISNUMBER(H14))),"rate",IF(AND(O14=0,G14=9,OR(F14="Firm",F14="Estimate"),ISNUMBER(H14)),"base",IF(OR(C14="",C14="Unclassified"),"unclass",IF(U14=1,"dup",IF(AND(Audit!$C$19="Yes",O14=1,NOT(ISNUMBER(Audit!$M$66))),"noagree",""))))))))) | Y14: =IF(ISNUMBER(Audit!$K$66),Audit!$K$66,0) -> 0 | Z14: =IF(AND(F14="Firm",O14=1,ISNUMBER(J14)),L14*J14,0) -> 0 | AE14: Conditional unpriced count | AF14: =COUNTIFS($F$2:$F$51,"If required",$O$2:$O$51,0) -> 0 | AH14: 13 | AI14: =IFERROR(SMALL($J$70:$J$470,AH14),"") | AJ14: =IF(AI14="","",MATCH(AI14,$J$70:$J$470,0)) | AL14: 13 | AM14: =IFERROR(SMALL($K$70:$K$470,AL14),"") | AN14: =IF(AM14="","",MATCH(AM14,$K$70:$K$470,0))
